Workbook

Sheet People
A1: Obligatorio | B1: Opcional | C1: Opciona Indicativo país (+XX) XXXXX | D1: Obligatorio2 | E1: Opcional3 | F1: Opcional4 | G1: Opcional5 | H1: Opcional6 | I1: Opcional7 | J1: Opcional8 | K1: Opcional9 | L1: Opcional10 | M1: Opcional11 | N1: Opcional12 | O1: Opcional Documento identidad formateado | P1: Opcional Lugar Expedición Documento | Q1: Opcional Titulo | R1: Opcional Programa | S1: Opcional Programa Código y fecha | T1: Opcional Día Firma | U1: Opcional Nombre Firmante 1 | V1: Opcional Nombre Firmante 2 | W1: Opcional Nombre firmante 3 | X1: Opcional Numero Libro | Y1: Opcional Numero Folio | Z1: Opcional Numero Registro | AA1: Opcional Numero Acta | AB1: Opcional Fecha de Emision | AC1: Opcional Contralmirante Ceremonia
A2: NOMBRES | B2: APELLIDOS | C2: TELEFONO | D2: EMAIL | E2: TIPODOCUMENTO | F2: NUMERODOCUMENTO | G2: LUGAREXPEDICION | H2: FECHAEXPEDICION | I2: GENERO | J2: FECHANACIMIENTO | K2: DIRECCION | L2: EMAIL2 | M2: TELEFONO2 | N2: COMENTARIOS | O2: docformato | P2: lugarexpi | Q2: titulo | R2: programa | S2: programa | T2: fechagrado | U2: nomfirma1 | V2: nomfirma2 | W2: nomfirma3 | X2: li | Y2: fo | Z2: numre | AA2: ndi | AB2: fechaemite | AC2: calceremonia
E4: =IFERROR(VLOOKUP(O4,Parameters!C:D,2,FALSE),"") | Q4: =IF(_xlfn.XLOOKUP(People!$R4,Parameters!N:N,Parameters!M:M)=0,"",_xlfn.XLOOKUP(People!$R4,Parameters!N:N,Parameters!M:M)) | S4: =IFERROR(IF(_xlfn.XLOOKUP(R4,Parameters!N:N,Parameters!L:L)=0,"",_xlfn.XLOOKUP(R4,Parameters!N:N,Parameters!L:L)),"")
E5: =IFERROR(VLOOKUP(O5,Parameters!C:D,2,FALSE),"") | Q5: =IF(_xlfn.XLOOKUP(People!$R5,Parameters!N:N,Parameters!M:M)=0,"",_xlfn.XLOOKUP(People!$R5,Parameters!N:N,Parameters!M:M)) | S5: =IFERROR(IF(_xlfn.XLOOKUP(R5,Parameters!N:N,Parameters!L:L)=0,"",_xlfn.XLOOKUP(R5,Parameters!N:N,Parameters!L:L)),"")
E6: =IFERROR(VLOOKUP(O6,Parameters!C:D,2,FALSE),"") | Q6: =IF(_xlfn.XLOOKUP(People!$R6,Parameters!N:N,Parameters!M:M)=0,"",_xlfn.XLOOKUP(People!$R6,Parameters!N:N,Parameters!M:M)) | S6: =IFERROR(IF(_xlfn.XLOOKUP(R6,Parameters!N:N,Parameters!L:L)=0,"",_xlfn.XLOOKUP(R6,Parameters!N:N,Parameters!L:L)),"")
E7: =IFERROR(VLOOKUP(O7,Parameters!C:D,2,FALSE),"") | Q7: =IF(_xlfn.XLOOKUP(People!$R7,Parameters!N:N,Parameters!M:M)=0,"",_xlfn.XLOOKUP(People!$R7,Parameters!N:N,Parameters!M:M)) | S7: =IFERROR(IF(_xlfn.XLOOKUP(R7,Parameters!N:N,Parameters!L:L)=0,"",_xlfn.XLOOKUP(R7,Parameters!N:N,Parameters!L:L)),"")
E8: =IFERROR(VLOOKUP(O8,Parameters!C:D,2,FALSE),"") | Q8: =IF(_xlfn.XLOOKUP(People!$R8,Parameters!N:N,Parameters!M:M)=0,"",_xlfn.XLOOKUP(People!$R8,Parameters!N:N,Parameters!M:M)) | S8: =IFERROR(IF(_xlfn.XLOOKUP(R8,Parameters!N:N,Parameters!L:L)=0,"",_xlfn.XLOOKUP(R8,Parameters!N:N,Parameters!L:L)),"")
E9: =IFERROR(VLOOKUP(O9,Parameters!C:D,2,FALSE),"") | Q9: =IF(_xlfn.XLOOKUP(People!$R9,Parameters!N:N,Parameters!M:M)=0,"",_xlfn.XLOOKUP(People!$R9,Parameters!N:N,Parameters!M:M)) | S9: =IFERROR(IF(_xlfn.XLOOKUP(R9,Parameters!N:N,Parameters!L:L)=0,"",_xlfn.XLOOKUP(R9,Parameters!N:N,Parameters!L:L)),"")
E10: =IFERROR(VLOOKUP(O10,Parameters!C:D,2,FALSE),"") | Q10: =IF(_xlfn.XLOOKUP(People!$R10,Parameters!N:N,Parameters!M:M)=0,"",_xlfn.XLOOKUP(People!$R10,Parameters!N:N,Parameters!M:M)) | S10: =IFERROR(IF(_xlfn.XLOOKUP(R10,Parameters!N:N,Parameters!L:L)=0,"",_xlfn.XLOOKUP(R10,Parameters!N:N,Parameters!L:L)),"")
E11: =IFERROR(VLOOKUP(O11,Parameters!C:D,2,FALSE),"") | Q11: =IF(_xlfn.XLOOKUP(People!$R11,Parameters!N:N,Parameters!M:M)=0,"",_xlfn.XLOOKUP(People!$R11,Parameters!N:N,Parameters!M:M)) | S11: =IFERROR(IF(_xlfn.XLOOKUP(R11,Parameters!N:N,Parameters!L:L)=0,"",_xlfn.XLOOKUP(R11,Parameters!N:N,Parameters!L:L)),"")
E12: =IFERROR(VLOOKUP(O12,Parameters!C:D,2,FALSE),"") | Q12: =IF(_xlfn.XLOOKUP(People!$R12,Parameters!N:N,Parameters!M:M)=0,"",_xlfn.XLOOKUP(People!$R12,Parameters!N:N,Parameters!M:M)) | S12: =IFERROR(IF(_xlfn.XLOOKUP(R12,Parameters!N:N,Parameters!L:L)=0,"",_xlfn.XLOOKUP(R12,Parameters!N:N,Parameters!L:L)),"")
E13: =IFERROR(VLOOKUP(O13,Parameters!C:D,2,FALSE),"") | Q13: =IF(_xlfn.XLOOKUP(People!$R13,Parameters!N:N,Parameters!M:M)=0,"",_xlfn.XLOOKUP(People!$R13,Parameters!N:N,Parameters!M:M)) | S13: =IFERROR(IF(_xlfn.XLOOKUP(R13,Parameters!N:N,Parameters!L:L)=0,"",_xlfn.XLOOKUP(R13,Parameters!N:N,Parameters!L:L)),"")
E14: =IFERROR(VLOOKUP(O14,Parameters!C:D,2,FALSE),"") | Q14: =IF(_xlfn.XLOOKUP(People!$R14,Parameters!N:N,Parameters!M:M)=0,"",_xlfn.XLOOKUP(People!$R14,Parameters!N:N,Parameters!M:M)) | S14: =IFERROR(IF(_xlfn.XLOOKUP(R14,Parameters!N:N,Parameters!L:L)=0,"",_xlfn.XLOOKUP(R14,Parameters!N:N,Parameters!L:L)),"")
E15: =IFERROR(VLOOKUP(O15,Parameters!C:D,2,FALSE),"") | Q15: =IF(_xlfn.XLOOKUP(People!$R15,Parameters!N:N,Parameters!M:M)=0,"",_xlfn.XLOOKUP(People!$R15,Parameters!N:N,Parameters!M:M)) | S15: =IFERROR(IF(_xlfn.XLOOKUP(R15,Parameters!N:N,Parameters!L:L)=0,"",_xlfn.XLOOKUP(R15,Parameters!N:N,Parameters!L:L)),"")
... E17: =IFERROR(VLOOKUP(O17,Parameters!C:D,2,FALSE),"") | Q17: =IF(_xlfn.XLOOKUP(People!$R17,Parameters!N:N,Parameters!M:M)=0,"",_xlfn.XLOOKUP(People!$R17,Parameters!N:N,Parameters!M:M)) | S17: =IFERROR(IF(_xlfn.XLOOKUP(R17,Parameters!N:N,Parameters!L:L)=0,"",_xlfn.XLOOKUP(R17,Parameters!N:N,Parameters!L:L)),"")

Sheet Parameters
A1: Validación
D3: Countries Documents | F3: Gender | H3: docformato | J3: cargo firmante | L3: programa | M3: título | N3: Programa
C4: ID | D4: Albania - id | F4: M | H4: cédula de ciudadanía | J4: Secretario Académico | L4: 9488 del 15 de diciembre de 1999 | M4: Profesional en Ciencias Navales | N4: Ciencias Navales para Oficiales Navales
C5: pasaporte | D5: Albania - Passport | F5: F | H5: pasaporte | J5: Decano Académico | L5: 9487 del 15 de diciembre de 1999 | M5: Profesional en Ciencias Navales | N5: Ciencias Navales para Oficiales de Infantería de Marina
C6: ID | D6: Algeria - id | H6: tarjeta de identidad | J6: Director | L6: 9486 del 15 de diciembre de 1999 | M6: Profesional en Ciencias Náuticas Especialidad Puente | N6: Ciencias Náuticas para Oficiales Mercantes
C7: pasaporte | D7: Algeria - Passport | L7: 109800 del 24 de mayo de 2019 | M7: Profesional en Ciencias Náuticas Especialidad Máquinas | N7: Ciencias Náuticas para Oficiales Mercantes de Máquinas
D8: Argentina - CUIL | L8: 4057 del 21 de marzo de 1998 | M8: Administrador | N8: Administración
D9: Argentina - CUIT | L9: 354 del 21 de marzo de 1998 | M9: Administrador Marítimo | N9: Administración Marítima
D10: Argentina - DNI | L10: 358 del 21 de marzo de 1998 | M10: Oceanógrafo Físico | N10: Oceanografía Física
D11: Argentina - Pasaporte | F11: mes | L11: 102036 del 1 de noviembre de 2012 | M11: Ingeniero Naval | N11: Ingeniería Naval
D12: Australia - ABN | F12: enero | L12: 102417 del 25 de abril de 2013 | M12: Ingeniero Electrónico | N12: Ingeniería Electrónica
C13: pasaporte | D13: Australia - Passport | F13: febrero | L13: 10814 del 17 de octubre de 2000 | M13: Especialista en Logística | N13: Especialización en Logística
C14: ID | D14: Austria - id | F14: marzo | L14: 51609 del 21 de junio de 2005 | M14: Especialista en Política y Estrategia Marítima | N14: Especialización en Política y Estrategia Marítima
C15: pasaporte | D15: Austria - Passport | F15: abril | L15: 51779 del 2 de diciembre de 2005 | M15: Magíster en Gestión Logística | N15: Maestría en Gestión Logística
C16: ID | D16: Belgium - id | F16: mayo | L16: 21547 del 27 de abril de 2005 | M16: Magíster en Oceanografía | N16: Maestría en Oceanografía
C17: pasaporte | D17: Belgium - Passport | F17: junio | L17: 91478 del 24 de agosto de 2011 | M17: Magíster en Ingeniería Naval | N17: Maestría en Ingeniería Naval
C18: ID | D18: Bolivia - ID | F18: julio | L18: 90528 del 6 de diciembre de 2023 | M18: Doctor en Ciencias del Mar | N18: Doctorado en Ciencias del Mar
D19: Bolivia - Pasaporte | F19: agosto | L19: 355 del 21 de marzo de 1998 | M19: Ingeniero Naval - Especialidad Construcciones | N19: Ingeniería Naval - Especialidad Construcciones
D20: Brasil - CPF | F20: septiembre | L20: 356 del 21 de marzo de 1998 | M20: Ingeniero Naval - Especialidad Electrónica | N20: Ingeniería Naval - Especialidad Electrónica
C21: pasaporte | D21: Brasil - Passport | F21: octubre | L21: 357 del 21 de marzo de 1998 | M21: Ingeniero Naval - Especialidad Mecánica | N21: Ingeniería Naval - Especialidad Mecánica
D22: Brasil - RG | F22: noviembre
C23: ID | D23: Bulgaria - id | F23: diciembre
C24: pasaporte | D24: Bulgaria - Passport
C25: ID | D25: Canada - id
C26: pasaporte | D26: Canada - Passport
D27: Chile - Cédula de identidad
D28: Chile - Pasaporte
D29: Chile - RUN
D30: Chile - RUT
D31: China - id
C32: pasaporte | D32: China - Passport
C33: cédula de ciudadanía | D33: Colombia - Cédula de ciudadanía
D34: Colombia - Cédula de extranjería
D35: Colombia - Cédula de identidad Civil
D36: Colombia - Clave Única Registro Población
D37: Colombia - Número de Identificación Extranjero
D38: Colombia - NIT
C39: pasaporte | D39: Colombia - Pasaporte
D40: Colombia - Registro civil
C41: tarjeta de identidad | D41: Colombia - Tarjeta de identidad
...
